<sdf version='1.6'>
  <model name='rrbot'>
    <link name='link1'>
      <pose frame=''>0 0 0 0 -0 0</pose>
      <inertial>
        <pose frame=''>0 0 1 0 -0 0</pose>
        <mass>1</mass>
        <inertia>
          <ixx>0.334167</ixx>
          <ixy>0</ixy>
          <ixz>0</ixz>
          <iyy>0.334167</iyy>
          <iyz>0</iyz>
          <izz>0.00166667</izz>
        </inertia>
      </inertial>
      <collision name='link1_collision'>
        <pose frame=''>0 0 1 0 -0 0</pose>
        <geometry>
          <box>
            <size>0.1 0.1 2</size>
          </box>
        </geometry>
      </collision>
      <visual name='link1_visual'>
        <pose frame=''>0 0 1 0 -0 0</pose>
        <geometry>
          <box>
            <size>0.1 0.1 2</size>
          </box>
        </geometry>
      </visual>
    </link>
    <joint name='fixed' type='fixed'>
      <child>link1</child>
      <parent>world</parent>
    </joint>
    <link name='link2'>
      <pose frame=''>0 0.1 1.95 0 -0 0</pose>
      <inertial>
        <pose frame=''>0 0 0.45 0 -0 0</pose>
        <mass>1</mass>
        <inertia>
          <ixx>0.0841667</ixx>
          <ixy>0</ixy>
          <ixz>0</ixz>
          <iyy>0.0841667</iyy>
          <iyz>0</iyz>
          <izz>0.00166667</izz>
        </inertia>
      </inertial>
      <collision name='link2_collision'>
        <pose frame=''>0 0 0.45 0 -0 0</pose>
        <geometry>
          <box>
            <size>0.1 0.1 1</size>
          </box>
        </geometry>
      </collision>
      <visual name='link2_visual'>
        <pose frame=''>0 0 0.45 0 -0 0</pose>
        <geometry>
          <box>
            <size>0.1 0.1 1</size>
          </box>
        </geometry>
      </visual>
    </link>
    <joint name='joint1' type='revolute'>
      <child>link2</child>
      <parent>link1</parent>
      <axis>
        <xyz>0 1 0</xyz>
        <limit>
          <lower>-1e+16</lower>
          <upper>1e+16</upper>
        </limit>
        <dynamics>
          <damping>0.7</damping>
          <friction>0</friction>
          <spring_reference>0</spring_reference>
          <spring_stiffness>0</spring_stiffness>
        </dynamics>
        <use_parent_model_frame>1</use_parent_model_frame>
      </axis>
    </joint>
    <link name='link3'>
      <pose frame=''>0 0.2 2.85 0 -0 0</pose>
      <inertial>
        <pose frame=''>0 0 0.45001 0 -0 0</pose>
        <mass>1.00002</mass>
        <inertia>
          <ixx>0.0841734</ixx>
          <ixy>0</ixy>
          <ixz>-2.24995e-07</ixz>
          <iyy>0.0841735</iyy>
          <iyz>0</iyz>
          <izz>0.00166869</izz>
        </inertia>
      </inertial>
      <collision name='link3_collision'>
        <pose frame=''>0 0 0.45 0 -0 0</pose>
        <geometry>
          <box>
            <size>0.1 0.1 1</size>
          </box>
        </geometry>
      </collision>
      <collision name='link3_fixed_joint_lump__camera_link_collision_1'>
        <pose frame=''>0.05 0 0.9 0 -0 0</pose>
        <geometry>
          <box>
            <size>0.05 0.05 0.05</size>
          </box>
        </geometry>
      </collision>
      <collision name='link3_fixed_joint_lump__hokuyo_link_collision_2'>
        <pose frame=''>0 0 0.975 0 -0 0</pose>
        <geometry>
          <box>
            <size>0.1 0.1 0.1</size>
          </box>
        </geometry>
      </collision>
      <visual name='link3_visual'>
        <pose frame=''>0 0 0.45 0 -0 0</pose>
        <geometry>
          <box>
            <size>0.1 0.1 1</size>
          </box>
        </geometry>
      </visual>
      <visual name='link3_fixed_joint_lump__camera_link_visual_1'>
        <pose frame=''>0.05 0 0.9 0 -0 0</pose>
        <geometry>
          <box>
            <size>0.05 0.05 0.05</size>
          </box>
        </geometry>
      </visual>
      <visual name='link3_fixed_joint_lump__hokuyo_link_visual_2'>
        <pose frame=''>0 0 0.975 0 -0 0</pose>
        <geometry>
          <box>
            <size>0.1 0.1 0.1</size>
          </box>
        </geometry>
      </visual>
    </link>
    <joint name='joint2' type='revolute'>
      <child>link3</child>
      <parent>link2</parent>
      <axis>
        <xyz>0 1 0</xyz>
        <limit>
          <lower>-1e+16</lower>
          <upper>1e+16</upper>
        </limit>
        <dynamics>
          <damping>0.7</damping>
          <friction>0</friction>
          <spring_reference>0</spring_reference>
          <spring_stiffness>0</spring_stiffness>
        </dynamics>
        <use_parent_model_frame>1</use_parent_model_frame>
      </axis>
    </joint>
  </model>
</sdf>
